Exception on /wizard/upload [POST]
Traceback (most recent call last):
  File "/home/jdomsic/venv/lib/python2.6/site-packages/flask/app.py", line 1817, in wsgi_app
    response = self.full_dispatch_request()
  File "/home/jdomsic/venv/lib/python2.6/site-packages/flask/app.py", line 1477, in full_dispatch_request
    rv = self.handle_user_exception(e)
  File "/home/jdomsic/venv/lib/python2.6/site-packages/flask/app.py", line 1381, in handle_user_exception
    reraise(exc_type, exc_value, tb)
  File "/home/jdomsic/venv/lib/python2.6/site-packages/flask/app.py", line 1475, in full_dispatch_request
    rv = self.dispatch_request()
  File "/home/jdomsic/venv/lib/python2.6/site-packages/flask/app.py", line 1461, in dispatch_request
    return self.view_functions[rule.endpoint](**req.view_args)
  File "message_collector.py", line 20, in collect_sensor_info
    db = get_db_connection()
  File "utils/database/connection.py", line 7, in get_db_connection
    name = app.cfg.db[0]
AttributeError: Configuration instance has no attribute 'db'
Exception on /wizard/upload [POST]
Traceback (most recent call last):
  File "/home/jdomsic/venv/lib/python2.6/site-packages/flask/app.py", line 1817, in wsgi_app
    response = self.full_dispatch_request()
  File "/home/jdomsic/venv/lib/python2.6/site-packages/flask/app.py", line 1477, in full_dispatch_request
    rv = self.handle_user_exception(e)
  File "/home/jdomsic/venv/lib/python2.6/site-packages/flask/app.py", line 1381, in handle_user_exception
    reraise(exc_type, exc_value, tb)
  File "/home/jdomsic/venv/lib/python2.6/site-packages/flask/app.py", line 1475, in full_dispatch_request
    rv = self.dispatch_request()
  File "/home/jdomsic/venv/lib/python2.6/site-packages/flask/app.py", line 1461, in dispatch_request
    return self.view_functions[rule.endpoint](**req.view_args)
  File "message_collector.py", line 20, in collect_sensor_info
    db = get_db_connection()
  File "utils/database/connection.py", line 7, in get_db_connection
    name = app.cfg.database[0]
AttributeError: Configuration instance has no attribute 'db'
Exception on /wizard/upload [POST]
Traceback (most recent call last):
  File "/home/jdomsic/venv/lib/python2.6/site-packages/flask/app.py", line 1817, in wsgi_app
    response = self.full_dispatch_request()
  File "/home/jdomsic/venv/lib/python2.6/site-packages/flask/app.py", line 1477, in full_dispatch_request
    rv = self.handle_user_exception(e)
  File "/home/jdomsic/venv/lib/python2.6/site-packages/flask/app.py", line 1381, in handle_user_exception
    reraise(exc_type, exc_value, tb)
  File "/home/jdomsic/venv/lib/python2.6/site-packages/flask/app.py", line 1475, in full_dispatch_request
    rv = self.dispatch_request()
  File "/home/jdomsic/venv/lib/python2.6/site-packages/flask/app.py", line 1461, in dispatch_request
    return self.view_functions[rule.endpoint](**req.view_args)
  File "message_collector.py", line 20, in collect_sensor_info
    db = get_db_connection()
  File "utils/database/connection.py", line 7, in get_db_connection
    name = app.cfg.database[0]
AttributeError: Configuration instance has no attribute 'db'
Exception on /wizard/upload [POST]
Traceback (most recent call last):
  File "/home/jdomsic/venv/lib/python2.6/site-packages/flask/app.py", line 1817, in wsgi_app
    response = self.full_dispatch_request()
  File "/home/jdomsic/venv/lib/python2.6/site-packages/flask/app.py", line 1477, in full_dispatch_request
    rv = self.handle_user_exception(e)
  File "/home/jdomsic/venv/lib/python2.6/site-packages/flask/app.py", line 1381, in handle_user_exception
    reraise(exc_type, exc_value, tb)
  File "/home/jdomsic/venv/lib/python2.6/site-packages/flask/app.py", line 1475, in full_dispatch_request
    rv = self.dispatch_request()
  File "/home/jdomsic/venv/lib/python2.6/site-packages/flask/app.py", line 1461, in dispatch_request
    return self.view_functions[rule.endpoint](**req.view_args)
  File "message_collector.py", line 20, in collect_sensor_info
    db = get_db_connection()
  File "utils/database/connection.py", line 7, in get_db_connection
    name = app.cfg.database[0]
AttributeError: Configuration instance has no attribute 'db'
Exception on /wizard/upload [POST]
Traceback (most recent call last):
  File "/home/jdomsic/venv/lib/python2.6/site-packages/flask/app.py", line 1817, in wsgi_app
    response = self.full_dispatch_request()
  File "/home/jdomsic/venv/lib/python2.6/site-packages/flask/app.py", line 1477, in full_dispatch_request
    rv = self.handle_user_exception(e)
  File "/home/jdomsic/venv/lib/python2.6/site-packages/flask/app.py", line 1381, in handle_user_exception
    reraise(exc_type, exc_value, tb)
  File "/home/jdomsic/venv/lib/python2.6/site-packages/flask/app.py", line 1475, in full_dispatch_request
    rv = self.dispatch_request()
  File "/home/jdomsic/venv/lib/python2.6/site-packages/flask/app.py", line 1461, in dispatch_request
    return self.view_functions[rule.endpoint](**req.view_args)
  File "message_collector.py", line 20, in collect_sensor_info
    db = get_db_connection(app)
  File "utils/database/connection.py", line 9, in get_db_connection
    return Connection(name, port)
  File "/home/jdomsic/venv/lib/python2.6/site-packages/pymongo/connection.py", line 236, in __init__
    max_pool_size, document_class, tz_aware, _connect, **kwargs)
  File "/home/jdomsic/venv/lib/python2.6/site-packages/pymongo/mongo_client.py", line 241, in __init__
    raise TypeError("port must be an instance of int")
TypeError: port must be an instance of int
Exception on /wizard/upload [POST]
Traceback (most recent call last):
  File "/home/jdomsic/venv/lib/python2.6/site-packages/flask/app.py", line 1817, in wsgi_app
    response = self.full_dispatch_request()
  File "/home/jdomsic/venv/lib/python2.6/site-packages/flask/app.py", line 1477, in full_dispatch_request
    rv = self.handle_user_exception(e)
  File "/home/jdomsic/venv/lib/python2.6/site-packages/flask/app.py", line 1381, in handle_user_exception
    reraise(exc_type, exc_value, tb)
  File "/home/jdomsic/venv/lib/python2.6/site-packages/flask/app.py", line 1475, in full_dispatch_request
    rv = self.dispatch_request()
  File "/home/jdomsic/venv/lib/python2.6/site-packages/flask/app.py", line 1461, in dispatch_request
    return self.view_functions[rule.endpoint](**req.view_args)
  File "message_collector.py", line 32, in collect_sensor_info
    mq, mq_channel = open_mq_channel(app.cfg.msg_queue_url)
  File "message_collector.py", line 68, in open_mq_channel
    channel = conn.connect()
  File "/home/jdomsic/venv/lib/python2.6/site-packages/pika/adapters/blocking_connection.py", line 230, in connect
    error = self._adapter_connect()
  File "/home/jdomsic/venv/lib/python2.6/site-packages/pika/adapters/blocking_connection.py", line 309, in _adapter_connect
    self.process_data_events()
  File "/home/jdomsic/venv/lib/python2.6/site-packages/pika/adapters/blocking_connection.py", line 240, in process_data_events
    if self._handle_read():
  File "/home/jdomsic/venv/lib/python2.6/site-packages/pika/adapters/blocking_connection.py", line 348, in _handle_read
    super(BlockingConnection, self)._handle_read()
  File "/home/jdomsic/venv/lib/python2.6/site-packages/pika/adapters/base_connection.py", line 343, in _handle_read
    return self._handle_error(error)
  File "/home/jdomsic/venv/lib/python2.6/site-packages/pika/adapters/base_connection.py", line 302, in _handle_error
    self._handle_disconnect()
  File "/home/jdomsic/venv/lib/python2.6/site-packages/pika/adapters/base_connection.py", line 248, in _handle_disconnect
    self._adapter_disconnect()
  File "/home/jdomsic/venv/lib/python2.6/site-packages/pika/adapters/blocking_connection.py", line 318, in _adapter_disconnect
    self._check_state_on_disconnect()
  File "/home/jdomsic/venv/lib/python2.6/site-packages/pika/adapters/blocking_connection.py", line 368, in _check_state_on_disconnect
    super(BlockingConnection, self)._check_state_on_disconnect()
  File "/home/jdomsic/venv/lib/python2.6/site-packages/pika/adapters/base_connection.py", line 149, in _check_state_on_disconnect
    raise exceptions.IncompatibleProtocolError
IncompatibleProtocolError
Exception on /wizard/upload [POST]
Traceback (most recent call last):
  File "/home/jdomsic/venv/lib/python2.6/site-packages/flask/app.py", line 1817, in wsgi_app
    response = self.full_dispatch_request()
  File "/home/jdomsic/venv/lib/python2.6/site-packages/flask/app.py", line 1477, in full_dispatch_request
    rv = self.handle_user_exception(e)
  File "/home/jdomsic/venv/lib/python2.6/site-packages/flask/app.py", line 1381, in handle_user_exception
    reraise(exc_type, exc_value, tb)
  File "/home/jdomsic/venv/lib/python2.6/site-packages/flask/app.py", line 1475, in full_dispatch_request
    rv = self.dispatch_request()
  File "/home/jdomsic/venv/lib/python2.6/site-packages/flask/app.py", line 1461, in dispatch_request
    return self.view_functions[rule.endpoint](**req.view_args)
  File "message_collector.py", line 32, in collect_sensor_info
    mq, mq_channel = open_mq_channel(app.cfg.msg_queue_url)
  File "message_collector.py", line 68, in open_mq_channel
    channel = conn.connect()
  File "/home/jdomsic/venv/lib/python2.6/site-packages/pika/adapters/blocking_connection.py", line 230, in connect
    error = self._adapter_connect()
  File "/home/jdomsic/venv/lib/python2.6/site-packages/pika/adapters/blocking_connection.py", line 309, in _adapter_connect
    self.process_data_events()
  File "/home/jdomsic/venv/lib/python2.6/site-packages/pika/adapters/blocking_connection.py", line 240, in process_data_events
    if self._handle_read():
  File "/home/jdomsic/venv/lib/python2.6/site-packages/pika/adapters/blocking_connection.py", line 348, in _handle_read
    super(BlockingConnection, self)._handle_read()
  File "/home/jdomsic/venv/lib/python2.6/site-packages/pika/adapters/base_connection.py", line 343, in _handle_read
    return self._handle_error(error)
  File "/home/jdomsic/venv/lib/python2.6/site-packages/pika/adapters/base_connection.py", line 302, in _handle_error
    self._handle_disconnect()
  File "/home/jdomsic/venv/lib/python2.6/site-packages/pika/adapters/base_connection.py", line 248, in _handle_disconnect
    self._adapter_disconnect()
  File "/home/jdomsic/venv/lib/python2.6/site-packages/pika/adapters/blocking_connection.py", line 318, in _adapter_disconnect
    self._check_state_on_disconnect()
  File "/home/jdomsic/venv/lib/python2.6/site-packages/pika/adapters/blocking_connection.py", line 368, in _check_state_on_disconnect
    super(BlockingConnection, self)._check_state_on_disconnect()
  File "/home/jdomsic/venv/lib/python2.6/site-packages/pika/adapters/base_connection.py", line 149, in _check_state_on_disconnect
    raise exceptions.IncompatibleProtocolError
IncompatibleProtocolError
Exception on /wizard/upload [POST]
Traceback (most recent call last):
  File "/home/jdomsic/venv/lib/python2.6/site-packages/flask/app.py", line 1817, in wsgi_app
    response = self.full_dispatch_request()
  File "/home/jdomsic/venv/lib/python2.6/site-packages/flask/app.py", line 1477, in full_dispatch_request
    rv = self.handle_user_exception(e)
  File "/home/jdomsic/venv/lib/python2.6/site-packages/flask/app.py", line 1381, in handle_user_exception
    reraise(exc_type, exc_value, tb)
  File "/home/jdomsic/venv/lib/python2.6/site-packages/flask/app.py", line 1475, in full_dispatch_request
    rv = self.dispatch_request()
  File "/home/jdomsic/venv/lib/python2.6/site-packages/flask/app.py", line 1461, in dispatch_request
    return self.view_functions[rule.endpoint](**req.view_args)
  File "message_collector.py", line 32, in collect_sensor_info
    mq, mq_channel = open_mq_channel(app.cfg.msg_queue_url)
  File "message_collector.py", line 68, in open_mq_channel
    channel = conn.connect()
  File "/home/jdomsic/venv/lib/python2.6/site-packages/pika/adapters/blocking_connection.py", line 230, in connect
    error = self._adapter_connect()
  File "/home/jdomsic/venv/lib/python2.6/site-packages/pika/adapters/blocking_connection.py", line 309, in _adapter_connect
    self.process_data_events()
  File "/home/jdomsic/venv/lib/python2.6/site-packages/pika/adapters/blocking_connection.py", line 240, in process_data_events
    if self._handle_read():
  File "/home/jdomsic/venv/lib/python2.6/site-packages/pika/adapters/blocking_connection.py", line 348, in _handle_read
    super(BlockingConnection, self)._handle_read()
  File "/home/jdomsic/venv/lib/python2.6/site-packages/pika/adapters/base_connection.py", line 343, in _handle_read
    return self._handle_error(error)
  File "/home/jdomsic/venv/lib/python2.6/site-packages/pika/adapters/base_connection.py", line 302, in _handle_error
    self._handle_disconnect()
  File "/home/jdomsic/venv/lib/python2.6/site-packages/pika/adapters/base_connection.py", line 248, in _handle_disconnect
    self._adapter_disconnect()
  File "/home/jdomsic/venv/lib/python2.6/site-packages/pika/adapters/blocking_connection.py", line 318, in _adapter_disconnect
    self._check_state_on_disconnect()
  File "/home/jdomsic/venv/lib/python2.6/site-packages/pika/adapters/blocking_connection.py", line 368, in _check_state_on_disconnect
    super(BlockingConnection, self)._check_state_on_disconnect()
  File "/home/jdomsic/venv/lib/python2.6/site-packages/pika/adapters/base_connection.py", line 149, in _check_state_on_disconnect
    raise exceptions.IncompatibleProtocolError
IncompatibleProtocolError
Exception on /wizard/upload [POST]
Traceback (most recent call last):
  File "/usr/local/lib/python2.7/dist-packages/flask/app.py", line 1817, in wsgi_app
    response = self.full_dispatch_request()
  File "/usr/local/lib/python2.7/dist-packages/flask/app.py", line 1477, in full_dispatch_request
    rv = self.handle_user_exception(e)
  File "/usr/local/lib/python2.7/dist-packages/flask/app.py", line 1381, in handle_user_exception
    reraise(exc_type, exc_value, tb)
  File "/usr/local/lib/python2.7/dist-packages/flask/app.py", line 1475, in full_dispatch_request
    rv = self.dispatch_request()
  File "/usr/local/lib/python2.7/dist-packages/flask/app.py", line 1461, in dispatch_request
    return self.view_functions[rule.endpoint](**req.view_args)
  File "message_collector.py", line 33, in collect_sensor_info
    mq, mq_channel = open_mq_channel(app.cfg.msg_queue_url)
  File "message_collector.py", line 68, in open_mq_channel
    channel = conn.connect()
  File "/usr/local/lib/python2.7/dist-packages/pika/adapters/blocking_connection.py", line 230, in connect
    error = self._adapter_connect()
  File "/usr/local/lib/python2.7/dist-packages/pika/adapters/blocking_connection.py", line 309, in _adapter_connect
    self.process_data_events()
  File "/usr/local/lib/python2.7/dist-packages/pika/adapters/blocking_connection.py", line 240, in process_data_events
    if self._handle_read():
  File "/usr/local/lib/python2.7/dist-packages/pika/adapters/blocking_connection.py", line 348, in _handle_read
    super(BlockingConnection, self)._handle_read()
  File "/usr/local/lib/python2.7/dist-packages/pika/adapters/base_connection.py", line 343, in _handle_read
    return self._handle_error(error)
  File "/usr/local/lib/python2.7/dist-packages/pika/adapters/base_connection.py", line 302, in _handle_error
    self._handle_disconnect()
  File "/usr/local/lib/python2.7/dist-packages/pika/adapters/base_connection.py", line 248, in _handle_disconnect
    self._adapter_disconnect()
  File "/usr/local/lib/python2.7/dist-packages/pika/adapters/blocking_connection.py", line 318, in _adapter_disconnect
    self._check_state_on_disconnect()
  File "/usr/local/lib/python2.7/dist-packages/pika/adapters/blocking_connection.py", line 368, in _check_state_on_disconnect
    super(BlockingConnection, self)._check_state_on_disconnect()
  File "/usr/local/lib/python2.7/dist-packages/pika/adapters/base_connection.py", line 149, in _check_state_on_disconnect
    raise exceptions.IncompatibleProtocolError
IncompatibleProtocolError
Exception on /wizard/upload [POST]
Traceback (most recent call last):
  File "/usr/local/lib/python2.7/dist-packages/flask/app.py", line 1817, in wsgi_app
    response = self.full_dispatch_request()
  File "/usr/local/lib/python2.7/dist-packages/flask/app.py", line 1477, in full_dispatch_request
    rv = self.handle_user_exception(e)
  File "/usr/local/lib/python2.7/dist-packages/flask/app.py", line 1381, in handle_user_exception
    reraise(exc_type, exc_value, tb)
  File "/usr/local/lib/python2.7/dist-packages/flask/app.py", line 1475, in full_dispatch_request
    rv = self.dispatch_request()
  File "/usr/local/lib/python2.7/dist-packages/flask/app.py", line 1461, in dispatch_request
    return self.view_functions[rule.endpoint](**req.view_args)
  File "message_collector.py", line 33, in collect_sensor_info
    mq, mq_channel = open_mq_channel(app.cfg.msg_queue_url)
  File "message_collector.py", line 68, in open_mq_channel
    channel = conn.connect()
  File "/usr/local/lib/python2.7/dist-packages/pika/adapters/blocking_connection.py", line 230, in connect
    error = self._adapter_connect()
  File "/usr/local/lib/python2.7/dist-packages/pika/adapters/blocking_connection.py", line 309, in _adapter_connect
    self.process_data_events()
  File "/usr/local/lib/python2.7/dist-packages/pika/adapters/blocking_connection.py", line 240, in process_data_events
    if self._handle_read():
  File "/usr/local/lib/python2.7/dist-packages/pika/adapters/blocking_connection.py", line 348, in _handle_read
    super(BlockingConnection, self)._handle_read()
  File "/usr/local/lib/python2.7/dist-packages/pika/adapters/base_connection.py", line 343, in _handle_read
    return self._handle_error(error)
  File "/usr/local/lib/python2.7/dist-packages/pika/adapters/base_connection.py", line 302, in _handle_error
    self._handle_disconnect()
  File "/usr/local/lib/python2.7/dist-packages/pika/adapters/base_connection.py", line 248, in _handle_disconnect
    self._adapter_disconnect()
  File "/usr/local/lib/python2.7/dist-packages/pika/adapters/blocking_connection.py", line 318, in _adapter_disconnect
    self._check_state_on_disconnect()
  File "/usr/local/lib/python2.7/dist-packages/pika/adapters/blocking_connection.py", line 368, in _check_state_on_disconnect
    super(BlockingConnection, self)._check_state_on_disconnect()
  File "/usr/local/lib/python2.7/dist-packages/pika/adapters/base_connection.py", line 149, in _check_state_on_disconnect
    raise exceptions.IncompatibleProtocolError
IncompatibleProtocolError
Exception on /wizard/upload [POST]
Traceback (most recent call last):
  File "/usr/local/lib/python2.7/dist-packages/flask/app.py", line 1817, in wsgi_app
    response = self.full_dispatch_request()
  File "/usr/local/lib/python2.7/dist-packages/flask/app.py", line 1477, in full_dispatch_request
    rv = self.handle_user_exception(e)
  File "/usr/local/lib/python2.7/dist-packages/flask/app.py", line 1381, in handle_user_exception
    reraise(exc_type, exc_value, tb)
  File "/usr/local/lib/python2.7/dist-packages/flask/app.py", line 1475, in full_dispatch_request
    rv = self.dispatch_request()
  File "/usr/local/lib/python2.7/dist-packages/flask/app.py", line 1461, in dispatch_request
    return self.view_functions[rule.endpoint](**req.view_args)
  File "message_collector.py", line 33, in collect_sensor_info
    mq, mq_channel = open_mq_channel(app.cfg.msg_queue_url)
  File "message_collector.py", line 68, in open_mq_channel
    channel = conn.connect()
  File "/usr/local/lib/python2.7/dist-packages/pika/adapters/blocking_connection.py", line 230, in connect
    error = self._adapter_connect()
  File "/usr/local/lib/python2.7/dist-packages/pika/adapters/blocking_connection.py", line 309, in _adapter_connect
    self.process_data_events()
  File "/usr/local/lib/python2.7/dist-packages/pika/adapters/blocking_connection.py", line 240, in process_data_events
    if self._handle_read():
  File "/usr/local/lib/python2.7/dist-packages/pika/adapters/blocking_connection.py", line 348, in _handle_read
    super(BlockingConnection, self)._handle_read()
  File "/usr/local/lib/python2.7/dist-packages/pika/adapters/base_connection.py", line 343, in _handle_read
    return self._handle_error(error)
  File "/usr/local/lib/python2.7/dist-packages/pika/adapters/base_connection.py", line 302, in _handle_error
    self._handle_disconnect()
  File "/usr/local/lib/python2.7/dist-packages/pika/adapters/base_connection.py", line 248, in _handle_disconnect
    self._adapter_disconnect()
  File "/usr/local/lib/python2.7/dist-packages/pika/adapters/blocking_connection.py", line 318, in _adapter_disconnect
    self._check_state_on_disconnect()
  File "/usr/local/lib/python2.7/dist-packages/pika/adapters/blocking_connection.py", line 368, in _check_state_on_disconnect
    super(BlockingConnection, self)._check_state_on_disconnect()
  File "/usr/local/lib/python2.7/dist-packages/pika/adapters/base_connection.py", line 149, in _check_state_on_disconnect
    raise exceptions.IncompatibleProtocolError
IncompatibleProtocolError
Exception on /wizard/upload [POST]
Traceback (most recent call last):
  File "/usr/local/lib/python2.7/dist-packages/flask/app.py", line 1817, in wsgi_app
    response = self.full_dispatch_request()
  File "/usr/local/lib/python2.7/dist-packages/flask/app.py", line 1477, in full_dispatch_request
    rv = self.handle_user_exception(e)
  File "/usr/local/lib/python2.7/dist-packages/flask/app.py", line 1381, in handle_user_exception
    reraise(exc_type, exc_value, tb)
  File "/usr/local/lib/python2.7/dist-packages/flask/app.py", line 1475, in full_dispatch_request
    rv = self.dispatch_request()
  File "/usr/local/lib/python2.7/dist-packages/flask/app.py", line 1461, in dispatch_request
    return self.view_functions[rule.endpoint](**req.view_args)
  File "message_collector.py", line 36, in collect_sensor_info
    send_to_mq(msg, mq_channel, app.cfg.exchange, '')
  File "message_collector.py", line 67, in send_to_mq
    channel.basic_publish(exchange=exchange, routing_key=routing_key, body=msg)
  File "/usr/local/lib/python2.7/dist-packages/pika/adapters/blocking_connection.py", line 572, in basic_publish
    (properties, body), False)
  File "/usr/local/lib/python2.7/dist-packages/pika/adapters/blocking_connection.py", line 1159, in _send_method
    self.connection.send_method(self.channel_number, method_frame, content)
  File "/usr/local/lib/python2.7/dist-packages/pika/adapters/blocking_connection.py", line 274, in send_method
    self._send_method(channel_number, method_frame, content)
  File "/usr/local/lib/python2.7/dist-packages/pika/connection.py", line 1519, in _send_method
    content[1][start:end]))
TypeError: unhashable type
Exception on /wizard/upload [POST]
Traceback (most recent call last):
  File "/usr/local/lib/python2.7/dist-packages/flask/app.py", line 1817, in wsgi_app
    response = self.full_dispatch_request()
  File "/usr/local/lib/python2.7/dist-packages/flask/app.py", line 1477, in full_dispatch_request
    rv = self.handle_user_exception(e)
  File "/usr/local/lib/python2.7/dist-packages/flask/app.py", line 1381, in handle_user_exception
    reraise(exc_type, exc_value, tb)
  File "/usr/local/lib/python2.7/dist-packages/flask/app.py", line 1475, in full_dispatch_request
    rv = self.dispatch_request()
  File "/usr/local/lib/python2.7/dist-packages/flask/app.py", line 1461, in dispatch_request
    return self.view_functions[rule.endpoint](**req.view_args)
  File "message_collector.py", line 36, in collect_sensor_info
    send_to_mq(str(msg), mq_channel, app.cfg.exchange, '')
  File "message_collector.py", line 67, in send_to_mq
    channel.basic_publish(exchange=exchange, routing_key=routing_key, body=msg)
  File "/usr/local/lib/python2.7/dist-packages/pika/adapters/blocking_connection.py", line 572, in basic_publish
    (properties, body), False)
  File "/usr/local/lib/python2.7/dist-packages/pika/adapters/blocking_connection.py", line 1159, in _send_method
    self.connection.send_method(self.channel_number, method_frame, content)
  File "/usr/local/lib/python2.7/dist-packages/pika/adapters/blocking_connection.py", line 274, in send_method
    self._send_method(channel_number, method_frame, content)
  File "/usr/local/lib/python2.7/dist-packages/pika/connection.py", line 1510, in _send_method
    self._send_frame(frame.Header(channel_number, length, content[0]))
  File "/usr/local/lib/python2.7/dist-packages/pika/adapters/blocking_connection.py", line 422, in _send_frame
    self.process_data_events()
  File "/usr/local/lib/python2.7/dist-packages/pika/adapters/blocking_connection.py", line 240, in process_data_events
    if self._handle_read():
  File "/usr/local/lib/python2.7/dist-packages/pika/adapters/blocking_connection.py", line 348, in _handle_read
    super(BlockingConnection, self)._handle_read()
  File "/usr/local/lib/python2.7/dist-packages/pika/adapters/base_connection.py", line 351, in _handle_read
    self._on_data_available(data)
  File "/usr/local/lib/python2.7/dist-packages/pika/connection.py", line 1285, in _on_data_available
    self._process_frame(frame_value)
  File "/usr/local/lib/python2.7/dist-packages/pika/connection.py", line 1352, in _process_frame
    if self._process_callbacks(frame_value):
  File "/usr/local/lib/python2.7/dist-packages/pika/connection.py", line 1322, in _process_callbacks
    frame_value)                 # Args
  File "/usr/local/lib/python2.7/dist-packages/pika/callback.py", line 61, in wrapper
    return function(*tuple(args), **kwargs)
  File "/usr/local/lib/python2.7/dist-packages/pika/callback.py", line 92, in wrapper
    return function(*args, **kwargs)
  File "/usr/local/lib/python2.7/dist-packages/pika/callback.py", line 232, in process
    callback(*args, **keywords)
  File "/usr/local/lib/python2.7/dist-packages/pika/adapters/blocking_connection.py", line 1059, in _on_close
    method_frame.method.reply_text)
ChannelClosed: (404, "NOT_FOUND - no exchange 'master' in vhost '/'")
Exception on /wizard/upload [POST]
Traceback (most recent call last):
  File "/home/jdomsic/venv/lib/python2.6/site-packages/flask/app.py", line 1817, in wsgi_app
    response = self.full_dispatch_request()
  File "/home/jdomsic/venv/lib/python2.6/site-packages/flask/app.py", line 1477, in full_dispatch_request
    rv = self.handle_user_exception(e)
  File "/home/jdomsic/venv/lib/python2.6/site-packages/flask/app.py", line 1381, in handle_user_exception
    reraise(exc_type, exc_value, tb)
  File "/home/jdomsic/venv/lib/python2.6/site-packages/flask/app.py", line 1475, in full_dispatch_request
    rv = self.dispatch_request()
  File "/home/jdomsic/venv/lib/python2.6/site-packages/flask/app.py", line 1461, in dispatch_request
    return self.view_functions[rule.endpoint](**req.view_args)
  File "message_collector.py", line 34, in collect_sensor_info
    data = get_received_data(request.data)
  File "message_collector.py", line 45, in get_received_data
    return json.loads(raw_data)
  File "/usr/lib/python2.6/json/__init__.py", line 307, in loads
    return _default_decoder.decode(s)
  File "/usr/lib/python2.6/json/decoder.py", line 319, in decode
    obj, end = self.raw_decode(s, idx=_w(s, 0).end())
  File "/usr/lib/python2.6/json/decoder.py", line 338, in raw_decode
    raise ValueError("No JSON object could be decoded")
ValueError: No JSON object could be decoded
Exception on /wizard/upload [POST]
Traceback (most recent call last):
  File "/home/jdomsic/venv/lib/python2.6/site-packages/flask/app.py", line 1817, in wsgi_app
    response = self.full_dispatch_request()
  File "/home/jdomsic/venv/lib/python2.6/site-packages/flask/app.py", line 1477, in full_dispatch_request
    rv = self.handle_user_exception(e)
  File "/home/jdomsic/venv/lib/python2.6/site-packages/flask/app.py", line 1381, in handle_user_exception
    reraise(exc_type, exc_value, tb)
  File "/home/jdomsic/venv/lib/python2.6/site-packages/flask/app.py", line 1475, in full_dispatch_request
    rv = self.dispatch_request()
  File "/home/jdomsic/venv/lib/python2.6/site-packages/flask/app.py", line 1461, in dispatch_request
    return self.view_functions[rule.endpoint](**req.view_args)
  File "message_collector.py", line 34, in collect_sensor_info
    data = get_received_data(request.data)
  File "message_collector.py", line 45, in get_received_data
    return json.loads(raw_data)
  File "/usr/lib/python2.6/json/__init__.py", line 307, in loads
    return _default_decoder.decode(s)
  File "/usr/lib/python2.6/json/decoder.py", line 319, in decode
    obj, end = self.raw_decode(s, idx=_w(s, 0).end())
  File "/usr/lib/python2.6/json/decoder.py", line 338, in raw_decode
    raise ValueError("No JSON object could be decoded")
ValueError: No JSON object could be decoded
Exception on /wizard/upload [POST]
Traceback (most recent call last):
  File "/home/jdomsic/venv/lib/python2.6/site-packages/flask/app.py", line 1817, in wsgi_app
    response = self.full_dispatch_request()
  File "/home/jdomsic/venv/lib/python2.6/site-packages/flask/app.py", line 1477, in full_dispatch_request
    rv = self.handle_user_exception(e)
  File "/home/jdomsic/venv/lib/python2.6/site-packages/flask/app.py", line 1381, in handle_user_exception
    reraise(exc_type, exc_value, tb)
  File "/home/jdomsic/venv/lib/python2.6/site-packages/flask/app.py", line 1475, in full_dispatch_request
    rv = self.dispatch_request()
  File "/home/jdomsic/venv/lib/python2.6/site-packages/flask/app.py", line 1461, in dispatch_request
    return self.view_functions[rule.endpoint](**req.view_args)
  File "message_collector.py", line 34, in collect_sensor_info
    data = get_received_data(request.data)
  File "message_collector.py", line 45, in get_received_data
    return json.loads(raw_data)
NameError: global name 'json' is not defined
Exception on /wizard/upload [POST]
Traceback (most recent call last):
  File "/home/jdomsic/venv/lib/python2.6/site-packages/flask/app.py", line 1817, in wsgi_app
    response = self.full_dispatch_request()
  File "/home/jdomsic/venv/lib/python2.6/site-packages/flask/app.py", line 1477, in full_dispatch_request
    rv = self.handle_user_exception(e)
  File "/home/jdomsic/venv/lib/python2.6/site-packages/flask/app.py", line 1381, in handle_user_exception
    reraise(exc_type, exc_value, tb)
  File "/home/jdomsic/venv/lib/python2.6/site-packages/flask/app.py", line 1475, in full_dispatch_request
    rv = self.dispatch_request()
  File "/home/jdomsic/venv/lib/python2.6/site-packages/flask/app.py", line 1461, in dispatch_request
    return self.view_functions[rule.endpoint](**req.view_args)
  File "message_collector.py", line 34, in collect_sensor_info
    mq, mq_channel = open_mq_channel(app.cfg.msg_queue_url)
  File "message_collector.py", line 45, in get_received_data
    def get_received_data(raw_data):
NameError: global name 'json' is not defined
